[2024-04-02T12:01:52.997+0000] {taskinstance.py:1979} INFO - Dependencies all met for dep_context=non-requeueable deps ti=<TaskInstance: tb_gsi_bh.copy_to_bigquery scheduled__2024-04-01T00:00:00+00:00 [queued]>
[2024-04-02T12:01:53.034+0000] {taskinstance.py:1979} INFO - Dependencies all met for dep_context=requeueable deps ti=<TaskInstance: tb_gsi_bh.copy_to_bigquery scheduled__2024-04-01T00:00:00+00:00 [queued]>
[2024-04-02T12:01:53.035+0000] {taskinstance.py:2193} INFO - Starting attempt 1 of 2
[2024-04-02T12:01:53.100+0000] {taskinstance.py:2217} INFO - Executing <Task(GCSToBigQueryOperator): copy_to_bigquery> on 2024-04-01 00:00:00+00:00
[2024-04-02T12:01:53.119+0000] {standard_task_runner.py:60} INFO - Started process 80 to run task
[2024-04-02T12:01:53.150+0000] {standard_task_runner.py:87} INFO - Running: ['***', 'tasks', 'run', 'tb_gsi_bh', 'copy_to_bigquery', 'scheduled__2024-04-01T00:00:00+00:00', '--job-id', '60', '--raw', '--subdir', 'DAGS_FOLDER/GSIBH.py', '--cfg-path', '/tmp/tmpx9xdp4mv']
[2024-04-02T12:01:53.166+0000] {standard_task_runner.py:88} INFO - Job 60: Subtask copy_to_bigquery
[2024-04-02T12:01:53.377+0000] {task_command.py:423} INFO - Running <TaskInstance: tb_gsi_bh.copy_to_bigquery scheduled__2024-04-01T00:00:00+00:00 [running]> on host 15476aa6430d
[2024-04-02T12:01:53.817+0000] {taskinstance.py:2513} INFO - Exporting env vars: AIRFLOW_CTX_DAG_OWNER='***' AIRFLOW_CTX_DAG_ID='tb_gsi_bh' AIRFLOW_CTX_TASK_ID='copy_to_bigquery' AIRFLOW_CTX_EXECUTION_DATE='2024-04-01T00:00:00+00:00' AIRFLOW_CTX_TRY_NUMBER='1' AIRFLOW_CTX_DAG_RUN_ID='scheduled__2024-04-01T00:00:00+00:00'
[2024-04-02T12:01:53.874+0000] {connection.py:269} WARNING - Connection schemes (type: google_cloud_platform) shall not contain '_' according to RFC3986.
[2024-04-02T12:01:53.913+0000] {base.py:83} INFO - Using connection ID 'google_cloud_default' for task execution.
[2024-04-02T12:01:53.917+0000] {gcs_to_bigquery.py:379} INFO - Using existing BigQuery table for storing data...
[2024-04-02T12:01:53.954+0000] {taskinstance.py:2731} ERROR - Task failed with exception
Traceback (most recent call last):
  File "/home/airflow/.local/lib/python3.8/site-packages/airflow/models/taskinstance.py", line 444, in _execute_task
    result = _execute_callable(context=context, **execute_callable_kwargs)
  File "/home/airflow/.local/lib/python3.8/site-packages/airflow/models/taskinstance.py", line 414, in _execute_callable
    return execute_callable(context=context, **execute_callable_kwargs)
  File "/home/airflow/.local/lib/python3.8/site-packages/airflow/providers/google/cloud/transfers/gcs_to_bigquery.py", line 380, in execute
    self.configuration = self._use_existing_table()
  File "/home/airflow/.local/lib/python3.8/site-packages/airflow/providers/google/cloud/transfers/gcs_to_bigquery.py", line 582, in _use_existing_table
    default_project_id=self.hook.project_id,
  File "/home/airflow/.local/lib/python3.8/site-packages/airflow/providers/google/common/hooks/base_google.py", line 372, in project_id
    _, project_id = self.get_credentials_and_project_id()
  File "/home/airflow/.local/lib/python3.8/site-packages/airflow/providers/google/common/hooks/base_google.py", line 284, in get_credentials_and_project_id
    credentials, project_id = get_credentials_and_project_id(
  File "/home/airflow/.local/lib/python3.8/site-packages/airflow/providers/google/cloud/utils/credentials_provider.py", line 362, in get_credentials_and_project_id
    return _CredentialProvider(*args, **kwargs).get_credentials_and_project()
  File "/home/airflow/.local/lib/python3.8/site-packages/airflow/providers/google/cloud/utils/credentials_provider.py", line 213, in __init__
    raise AirflowException(
airflow.exceptions.AirflowException: The `keyfile_dict`, `key_path`, and `key_secret_name` fields are all mutually exclusive. Please provide only one value.
[2024-04-02T12:01:54.012+0000] {taskinstance.py:1149} INFO - Marking task as UP_FOR_RETRY. dag_id=tb_gsi_bh, task_id=copy_to_bigquery, execution_date=20240401T000000, start_date=20240402T120152, end_date=20240402T120154
[2024-04-02T12:01:54.092+0000] {standard_task_runner.py:107} ERROR - Failed to execute job 60 for task copy_to_bigquery (The `keyfile_dict`, `key_path`, and `key_secret_name` fields are all mutually exclusive. Please provide only one value.; 80)
[2024-04-02T12:01:54.146+0000] {local_task_job_runner.py:234} INFO - Task exited with return code 1
[2024-04-02T12:01:54.228+0000] {taskinstance.py:3312} INFO - 0 downstream tasks scheduled from follow-on schedule check
[2024-04-02T22:19:44.872+0000] {taskinstance.py:1979} INFO - Dependencies all met for dep_context=non-requeueable deps ti=<TaskInstance: tb_gsi_bh.copy_to_bigquery scheduled__2024-04-01T00:00:00+00:00 [queued]>
[2024-04-02T22:19:44.888+0000] {taskinstance.py:1979} INFO - Dependencies all met for dep_context=requeueable deps ti=<TaskInstance: tb_gsi_bh.copy_to_bigquery scheduled__2024-04-01T00:00:00+00:00 [queued]>
[2024-04-02T22:19:44.890+0000] {taskinstance.py:2193} INFO - Starting attempt 1 of 2
[2024-04-02T22:19:44.923+0000] {taskinstance.py:2217} INFO - Executing <Task(GCSToBigQueryOperator): copy_to_bigquery> on 2024-04-01 00:00:00+00:00
[2024-04-02T22:19:44.940+0000] {standard_task_runner.py:60} INFO - Started process 8928 to run task
[2024-04-02T22:19:44.948+0000] {standard_task_runner.py:87} INFO - Running: ['***', 'tasks', 'run', 'tb_gsi_bh', 'copy_to_bigquery', 'scheduled__2024-04-01T00:00:00+00:00', '--job-id', '64', '--raw', '--subdir', 'DAGS_FOLDER/GSIBH.py', '--cfg-path', '/tmp/tmpawnf_8ea']
[2024-04-02T22:19:44.956+0000] {standard_task_runner.py:88} INFO - Job 64: Subtask copy_to_bigquery
[2024-04-02T22:19:45.083+0000] {task_command.py:423} INFO - Running <TaskInstance: tb_gsi_bh.copy_to_bigquery scheduled__2024-04-01T00:00:00+00:00 [running]> on host 15476aa6430d
[2024-04-02T22:19:45.278+0000] {taskinstance.py:2513} INFO - Exporting env vars: AIRFLOW_CTX_DAG_OWNER='***' AIRFLOW_CTX_DAG_ID='tb_gsi_bh' AIRFLOW_CTX_TASK_ID='copy_to_bigquery' AIRFLOW_CTX_EXECUTION_DATE='2024-04-01T00:00:00+00:00' AIRFLOW_CTX_TRY_NUMBER='1' AIRFLOW_CTX_DAG_RUN_ID='scheduled__2024-04-01T00:00:00+00:00'
[2024-04-02T22:19:45.304+0000] {connection.py:269} WARNING - Connection schemes (type: google_cloud_platform) shall not contain '_' according to RFC3986.
[2024-04-02T22:19:45.318+0000] {base.py:83} INFO - Using connection ID 'google_cloud_default' for task execution.
[2024-04-02T22:19:45.323+0000] {gcs_to_bigquery.py:379} INFO - Using existing BigQuery table for storing data...
[2024-04-02T22:19:45.369+0000] {taskinstance.py:2731} ERROR - Task failed with exception
Traceback (most recent call last):
  File "/home/airflow/.local/lib/python3.8/site-packages/airflow/models/taskinstance.py", line 444, in _execute_task
    result = _execute_callable(context=context, **execute_callable_kwargs)
  File "/home/airflow/.local/lib/python3.8/site-packages/airflow/models/taskinstance.py", line 414, in _execute_callable
    return execute_callable(context=context, **execute_callable_kwargs)
  File "/home/airflow/.local/lib/python3.8/site-packages/airflow/providers/google/cloud/transfers/gcs_to_bigquery.py", line 380, in execute
    self.configuration = self._use_existing_table()
  File "/home/airflow/.local/lib/python3.8/site-packages/airflow/providers/google/cloud/transfers/gcs_to_bigquery.py", line 582, in _use_existing_table
    default_project_id=self.hook.project_id,
  File "/home/airflow/.local/lib/python3.8/site-packages/airflow/providers/google/common/hooks/base_google.py", line 372, in project_id
    _, project_id = self.get_credentials_and_project_id()
  File "/home/airflow/.local/lib/python3.8/site-packages/airflow/providers/google/common/hooks/base_google.py", line 284, in get_credentials_and_project_id
    credentials, project_id = get_credentials_and_project_id(
  File "/home/airflow/.local/lib/python3.8/site-packages/airflow/providers/google/cloud/utils/credentials_provider.py", line 362, in get_credentials_and_project_id
    return _CredentialProvider(*args, **kwargs).get_credentials_and_project()
  File "/home/airflow/.local/lib/python3.8/site-packages/airflow/providers/google/cloud/utils/credentials_provider.py", line 213, in __init__
    raise AirflowException(
airflow.exceptions.AirflowException: The `keyfile_dict`, `key_path`, and `key_secret_name` fields are all mutually exclusive. Please provide only one value.
[2024-04-02T22:19:45.385+0000] {taskinstance.py:1149} INFO - Marking task as UP_FOR_RETRY. dag_id=tb_gsi_bh, task_id=copy_to_bigquery, execution_date=20240401T000000, start_date=20240402T221944, end_date=20240402T221945
[2024-04-02T22:19:45.421+0000] {standard_task_runner.py:107} ERROR - Failed to execute job 64 for task copy_to_bigquery (The `keyfile_dict`, `key_path`, and `key_secret_name` fields are all mutually exclusive. Please provide only one value.; 8928)
[2024-04-02T22:19:45.443+0000] {local_task_job_runner.py:234} INFO - Task exited with return code 1
[2024-04-02T22:19:45.478+0000] {taskinstance.py:3312} INFO - 0 downstream tasks scheduled from follow-on schedule check
