[2024-04-01T15:03:43.221+0000] {taskinstance.py:1979} INFO - Dependencies all met for dep_context=non-requeueable deps ti=<TaskInstance: tb_gsi_bh.copy_to_bigquery manual__2024-04-01T15:03:39.092921+00:00 [queued]>
[2024-04-01T15:03:43.234+0000] {taskinstance.py:1979} INFO - Dependencies all met for dep_context=requeueable deps ti=<TaskInstance: tb_gsi_bh.copy_to_bigquery manual__2024-04-01T15:03:39.092921+00:00 [queued]>
[2024-04-01T15:03:43.235+0000] {taskinstance.py:2193} INFO - Starting attempt 1 of 2
[2024-04-01T15:03:43.255+0000] {taskinstance.py:2217} INFO - Executing <Task(GCSToBigQueryOperator): copy_to_bigquery> on 2024-04-01 15:03:39.092921+00:00
[2024-04-01T15:03:43.267+0000] {standard_task_runner.py:60} INFO - Started process 479 to run task
[2024-04-01T15:03:43.276+0000] {standard_task_runner.py:87} INFO - Running: ['***', 'tasks', 'run', 'tb_gsi_bh', 'copy_to_bigquery', 'manual__2024-04-01T15:03:39.092921+00:00', '--job-id', '54', '--raw', '--subdir', 'DAGS_FOLDER/GSIBH.py', '--cfg-path', '/tmp/tmpm7ut0gil']
[2024-04-01T15:03:43.281+0000] {standard_task_runner.py:88} INFO - Job 54: Subtask copy_to_bigquery
[2024-04-01T15:03:43.348+0000] {task_command.py:423} INFO - Running <TaskInstance: tb_gsi_bh.copy_to_bigquery manual__2024-04-01T15:03:39.092921+00:00 [running]> on host 15476aa6430d
[2024-04-01T15:03:43.461+0000] {taskinstance.py:2513} INFO - Exporting env vars: AIRFLOW_CTX_DAG_OWNER='***' AIRFLOW_CTX_DAG_ID='tb_gsi_bh' AIRFLOW_CTX_TASK_ID='copy_to_bigquery' AIRFLOW_CTX_EXECUTION_DATE='2024-04-01T15:03:39.092921+00:00' AIRFLOW_CTX_TRY_NUMBER='1' AIRFLOW_CTX_DAG_RUN_ID='manual__2024-04-01T15:03:39.092921+00:00'
[2024-04-01T15:03:43.473+0000] {connection.py:269} WARNING - Connection schemes (type: google_cloud_platform) shall not contain '_' according to RFC3986.
[2024-04-01T15:03:43.476+0000] {base.py:83} INFO - Using connection ID 'google_cloud_default' for task execution.
[2024-04-01T15:03:43.478+0000] {gcs_to_bigquery.py:379} INFO - Using existing BigQuery table for storing data...
[2024-04-01T15:03:43.491+0000] {taskinstance.py:2731} ERROR - Task failed with exception
Traceback (most recent call last):
  File "/home/airflow/.local/lib/python3.8/site-packages/airflow/providers/google/common/hooks/base_google.py", line 268, in get_credentials_and_project_id
    keyfile_dict_json = json.loads(keyfile_dict)
  File "/usr/local/lib/python3.8/json/__init__.py", line 357, in loads
    return _default_decoder.decode(s)
  File "/usr/local/lib/python3.8/json/decoder.py", line 337, in decode
    obj, end = self.raw_decode(s, idx=_w(s, 0).end())
  File "/usr/local/lib/python3.8/json/decoder.py", line 355, in raw_decode
    raise JSONDecodeError("Expecting value", s, err.value) from None
json.decoder.JSONDecodeError: Expecting value: line 1 column 1 (char 0)

During handling of the above exception, another exception occurred:

Traceback (most recent call last):
  File "/home/airflow/.local/lib/python3.8/site-packages/airflow/models/taskinstance.py", line 444, in _execute_task
    result = _execute_callable(context=context, **execute_callable_kwargs)
  File "/home/airflow/.local/lib/python3.8/site-packages/airflow/models/taskinstance.py", line 414, in _execute_callable
    return execute_callable(context=context, **execute_callable_kwargs)
  File "/home/airflow/.local/lib/python3.8/site-packages/airflow/providers/google/cloud/transfers/gcs_to_bigquery.py", line 380, in execute
    self.configuration = self._use_existing_table()
  File "/home/airflow/.local/lib/python3.8/site-packages/airflow/providers/google/cloud/transfers/gcs_to_bigquery.py", line 582, in _use_existing_table
    default_project_id=self.hook.project_id,
  File "/home/airflow/.local/lib/python3.8/site-packages/airflow/providers/google/common/hooks/base_google.py", line 372, in project_id
    _, project_id = self.get_credentials_and_project_id()
  File "/home/airflow/.local/lib/python3.8/site-packages/airflow/providers/google/common/hooks/base_google.py", line 270, in get_credentials_and_project_id
    raise AirflowException("Invalid key JSON.")
airflow.exceptions.AirflowException: Invalid key JSON.
[2024-04-01T15:03:43.497+0000] {taskinstance.py:1149} INFO - Marking task as UP_FOR_RETRY. dag_id=tb_gsi_bh, task_id=copy_to_bigquery, execution_date=20240401T150339, start_date=20240401T150343, end_date=20240401T150343
[2024-04-01T15:03:43.514+0000] {standard_task_runner.py:107} ERROR - Failed to execute job 54 for task copy_to_bigquery (Invalid key JSON.; 479)
[2024-04-01T15:03:43.531+0000] {local_task_job_runner.py:234} INFO - Task exited with return code 1
[2024-04-01T15:03:43.554+0000] {taskinstance.py:3312} INFO - 0 downstream tasks scheduled from follow-on schedule check
